Workbook

Sheet Inputs
A1: Fernwood Goods: 13-week cash forecast inputs
A2: Synthetic brand. Blue cells are inputs; black cells are formulas. Values come from the corrected plan P&L (docs/fernwood_pnl.md) and the onboarded ledger's calendars.
A4: Input | B4: Value | C4: Source / note
A5: Forecast week 0 starts (Monday) | B5: 46321 | C5: Actuals through Oct 25, 2026
A6: Shopify gross sales, average history week | B6: 114581.13 | C6: Plan revenue x DTC mix, scaled to an average Jul-Oct week
A7: Amazon sales, average history week | B7: 11458.113 | C7: Plan revenue x Amazon mix
A8: Wholesale invoices, average history week | B8: 17187.169 | C8: Plan revenue x wholesale mix
A9: History seasonality (avg of Jul-Oct multipliers) | B9: =AVERAGE(B44:B47) -> 0.9125 | C9: Formula on the month table
A10: Refund rate | B10: 0.06 | C10: Plan: 6% of revenue
A11: Refund rate, January | B11: 0.09 | C11: Plan: post-holiday returns
A12: Payment processing fees | B12: 0.03 | C12: Plan: 3% of revenue
A13: Chargebacks | B13: 0.002 | C13: Default for the portfolio
A14: Share of a week's net paid out the following week | B14: 0.2857 | C14: About 2 of 7 days
A15: Amazon fees | B15: 0.3 | C15: Referral and FBA, portfolio default
A16: Faire share of wholesale | B16: 0.6 | C16: Kickoff call
A17: Faire pays after (weeks) | B17: 1 | C17: Kickoff call
A18: Hudson Mercantile share of wholesale | B18: 0.4 | C18: Kickoff call
A19: Hudson Mercantile pays after (weeks) | B19: 9 | C19: Net 60 plus processing
A20: Ad spend as share of Shopify sales | B20: 0.22 | C20: Plan: 22% of DTC; Meta 70%, Google 30%
A21: October ad spend per week (history) | B21: =Inputs!$B$6*Inputs!$B$20*B47/Inputs!$B$9 -> 27625.039 | C21: Formula: base x ad rate x Oct multiplier
A22: Software and other card spend per week | B22: 2307.6923 | C22: Plan: $10K a month, part of the $34K fixed
A23: Payroll per run (biweekly) | B23: 50000 | C23: Plan: $50K biweekly
A24: Fixed costs paid from the bank on the 1st | B24: 24000 | C24: Plan: $34K a month, less $10K paid on the card
A25: Sales tax remitted on the 20th, share of last month's Shopify sales | B25: 0.04 | C25: Plan
A26: Bank fees and other small payments per week | B26: 160.9375 | C26: Ledger
A27: Opening cash, Oct 26 | B27: 300000 | C27: Lowered from the first draft's $1.0M
A28: Cash buffer policy | B28: 300000 | C28: Founder's minimum
A29: Credit line limit | B29: 1500000 | C29: Illustrative
A30: Credit line drawn today | B30: 400000 | C30: Illustrative
A31: Credit line APR | B31: 0.11 | C31: Illustrative
A32: Draws are made in multiples of | B32: 25000 | C32: actions/vendor_rules.yaml
A33: BFCM week starts | B33: 46349
A34: BFCM week ends | B34: 46355
A35: Share of November sales in BFCM week | B35: 0.4 | C35: Seasonality assumption
A37: Sales seasonality by month (1.00 = May)
A38: January | B38: 0.7
A39: February | B39: 0.7
A40: March | B40: 0.85
A41: April | B41: 0.9
A42: May | B42: 1
...

Sheet Forecast
A1: Fernwood Goods: 13-week direct cash forecast (synthetic)
A2: Grey columns are history weeks used by lags and terms. Cash rows start in week 0. Positive = cash in.
A4: Week | B4: -12 | C4: -11 | D4: -10 | E4: -9 | F4: -8 | G4: -7 | H4: -6 | I4: -5 | J4: -4 | K4: -3 | L4: -2 | M4: -1 | N4: 0 | O4: 1 | P4: 2 | Q4: 3 | R4: 4 | S4: 5 | T4: 6 | U4: 7 | V4: 8 | W4: 9 | X4: 10 | Y4: 11 | Z4: 12
A5: Week starting | B5: =Inputs!$B$5+7*B4 -> 46237 | C5: =Inputs!$B$5+7*C4 -> 46244 | D5: =Inputs!$B$5+7*D4 -> 46251 | E5: =Inputs!$B$5+7*E4 -> 46258 | F5: =Inputs!$B$5+7*F4 -> 46265 | G5: =Inputs!$B$5+7*G4 -> 46272 | H5: =Inputs!$B$5+7*H4 -> 46279 | I5: =Inputs!$B$5+7*I4 -> 46286 | ... Z5: =Inputs!$B$5+7*Z4 -> 46405
A6: Sales multiplier vs average history week | B6: =SUMIFS(Calendar!$D$2:$D$176,Calendar!$B$2:$B$176,B$4)/7/Inputs!$B$9 -> 0.93150685 | C6: =SUMIFS(Calendar!$D$2:$D$176,Calendar!$B$2:$B$176,C$4)/7/Inputs!$B$9 -> 0.93150685 | D6: =SUMIFS(Calendar!$D$2:$D$176,Calendar!$B$2:$B$176,D$4)/7/Inputs!$B$9 -> 0.93150685 | E6: =SUMIFS(Calendar!$D$2:$D$176,Calendar!$B$2:$B$176,E$4)/7/Inputs!$B$9 -> 0.93150685 | F6: =SUMIFS(Calendar!$D$2:$D$176,Calendar!$B$2:$B$176,F$4)/7/Inputs!$B$9 -> 0.97847358 | G6: =SUMIFS(Calendar!$D$2:$D$176,Calendar!$B$2:$B$176,G$4)/7/Inputs!$B$9 -> 0.98630137 | H6: =SUMIFS(Calendar!$D$2:$D$176,Calendar!$B$2:$B$176,H$4)/7/Inputs!$B$9 -> 0.98630137 | I6: =SUMIFS(Calendar!$D$2:$D$176,Calendar!$B$2:$B$176,I$4)/7/Inputs!$B$9 -> 0.98630137 | ... Z6: =SUMIFS(Calendar!$D$2:$D$176,Calendar!$B$2:$B$176,Z$4)/7/Inputs!$B$9 -> 0.76712329
A8: Shopify gross sales | B8: =Inputs!$B$6*B6 -> 106733.1 | C8: =Inputs!$B$6*C6 -> 106733.1 | D8: =Inputs!$B$6*D6 -> 106733.1 | E8: =Inputs!$B$6*E6 -> 106733.1 | F8: =Inputs!$B$6*F6 -> 112114.61 | G8: =Inputs!$B$6*G6 -> 113011.52 | H8: =Inputs!$B$6*H6 -> 113011.52 | I8: =Inputs!$B$6*I6 -> 113011.52 | ... Z8: =Inputs!$B$6*Z6 -> 87897.851
A9: Refund rate | B9: =IF(MONTH(B5)=1,Inputs!$B$11,Inputs!$B$10) -> 0.06 | C9: =IF(MONTH(C5)=1,Inputs!$B$11,Inputs!$B$10) -> 0.06 | D9: =IF(MONTH(D5)=1,Inputs!$B$11,Inputs!$B$10) -> 0.06 | E9: =IF(MONTH(E5)=1,Inputs!$B$11,Inputs!$B$10) -> 0.06 | F9: =IF(MONTH(F5)=1,Inputs!$B$11,Inputs!$B$10) -> 0.06 | G9: =IF(MONTH(G5)=1,Inputs!$B$11,Inputs!$B$10) -> 0.06 | H9: =IF(MONTH(H5)=1,Inputs!$B$11,Inputs!$B$10) -> 0.06 | I9: =IF(MONTH(I5)=1,Inputs!$B$11,Inputs!$B$10) -> 0.06 | ... Z9: =IF(MONTH(Z5)=1,Inputs!$B$11,Inputs!$B$10) -> 0.09
A10: Refunds | B10: =B8*B9 -> 6403.9863 | C10: =C8*C9 -> 6403.9863 | D10: =D8*D9 -> 6403.9863 | E10: =E8*E9 -> 6403.9863 | F10: =F8*F9 -> 6726.8764 | G10: =G8*G9 -> 6780.6914 | H10: =H8*H9 -> 6780.6914 | I10: =I8*I9 -> 6780.6914 | ... Z10: =Z8*Z9 -> 7910.8066
A11: Processing fees | B11: =B8*Inputs!$B$12 -> 3201.9931 | C11: =C8*Inputs!$B$12 -> 3201.9931 | D11: =D8*Inputs!$B$12 -> 3201.9931 | E11: =E8*Inputs!$B$12 -> 3201.9931 | F11: =F8*Inputs!$B$12 -> 3363.4382 | G11: =G8*Inputs!$B$12 -> 3390.3457 | H11: =H8*Inputs!$B$12 -> 3390.3457 | I11: =I8*Inputs!$B$12 -> 3390.3457 | ... Z11: =Z8*Inputs!$B$12 -> 2636.9355
A12: Chargebacks | B12: =B8*Inputs!$B$13 -> 213.46621 | C12: =C8*Inputs!$B$13 -> 213.46621 | D12: =D8*Inputs!$B$13 -> 213.46621 | E12: =E8*Inputs!$B$13 -> 213.46621 | F12: =F8*Inputs!$B$13 -> 224.22921 | G12: =G8*Inputs!$B$13 -> 226.02305 | H12: =H8*Inputs!$B$13 -> 226.02305 | I12: =I8*Inputs!$B$13 -> 226.02305 | ... Z12: =Z8*Inputs!$B$13 -> 175.7957
A13: Shopify net sales | B13: =B8-B10-B11-B12 -> 96913.659 | C13: =C8-C10-C11-C12 -> 96913.659 | D13: =D8-D10-D11-D12 -> 96913.659 | E13: =E8-E10-E11-E12 -> 96913.659 | F13: =F8-F10-F11-F12 -> 101800.06 | G13: =G8-G10-G11-G12 -> 102614.46 | H13: =H8-H10-H11-H12 -> 102614.46 | I13: =I8-I10-I11-I12 -> 102614.46 | ... Z13: =Z8-Z10-Z11-Z12 -> 77174.313
A14: Shopify payouts | N14: =(1-Inputs!$B$14)*N13+Inputs!$B$14*M13 -> 121502.63 | O14: =(1-Inputs!$B$14)*O13+Inputs!$B$14*N13 -> 169416.44 | P14: =(1-Inputs!$B$14)*P13+Inputs!$B$14*O13 -> 187382.93 | Q14: =(1-Inputs!$B$14)*Q13+Inputs!$B$14*P13 -> 187382.93 | R14: =(1-Inputs!$B$14)*R13+Inputs!$B$14*Q13 -> 346725.35 | S14: =(1-Inputs!$B$14)*S13+Inputs!$B$14*R13 -> 248080.34 | T14: =(1-Inputs!$B$14)*T13+Inputs!$B$14*S13 -> 182628.04 | U14: =(1-Inputs!$B$14)*U13+Inputs!$B$14*T13 -> 182425.71 | ... Z14: =(1-Inputs!$B$14)*Z13+Inputs!$B$14*Y13 -> 77174.313
A16: Amazon sales | B16: =Inputs!$B$7*B6 -> 10673.31 | C16: =Inputs!$B$7*C6 -> 10673.31 | D16: =Inputs!$B$7*D6 -> 10673.31 | E16: =Inputs!$B$7*E6 -> 10673.31 | F16: =Inputs!$B$7*F6 -> 11211.461 | G16: =Inputs!$B$7*G6 -> 11301.152 | H16: =Inputs!$B$7*H6 -> 11301.152 | I16: =Inputs!$B$7*I6 -> 11301.152 | ... Z16: =Inputs!$B$7*Z6 -> 8789.7851
A17: Amazon settlements | N17: =IF(MOD(N$4,2)=0,(L16+M16)*(1-Inputs!$B$15),0) -> 17579.57 | O17: =IF(MOD(O$4,2)=0,(M16+N16)*(1-Inputs!$B$15),0) -> 0 | P17: =IF(MOD(P$4,2)=0,(N16+O16)*(1-Inputs!$B$15),0) -> 24043.611 | Q17: =IF(MOD(Q$4,2)=0,(O16+P16)*(1-Inputs!$B$15),0) -> 0 | R17: =IF(MOD(R$4,2)=0,(P16+Q16)*(1-Inputs!$B$15),0) -> 28891.642 | S17: =IF(MOD(S$4,2)=0,(Q16+R16)*(1-Inputs!$B$15),0) -> 0 | T17: =IF(MOD(T$4,2)=0,(R16+S16)*(1-Inputs!$B$15),0) -> 45761.478 | U17: =IF(MOD(U$4,2)=0,(S16+T16)*(1-Inputs!$B$15),0) -> 0 | ... Z17: =IF(MOD(Z$4,2)=0,(X16+Y16)*(1-Inputs!$B$15),0) -> 12305.699
A19: Faire invoices issued | B19: =Inputs!$B$8*Inputs!$B$16*B6 -> 9605.9794 | C19: =Inputs!$B$8*Inputs!$B$16*C6 -> 9605.9794 | D19: =Inputs!$B$8*Inputs!$B$16*D6 -> 9605.9794 | E19: =Inputs!$B$8*Inputs!$B$16*E6 -> 9605.9794 | F19: =Inputs!$B$8*Inputs!$B$16*F6 -> 10090.315 | G19: =Inputs!$B$8*Inputs!$B$16*G6 -> 10171.037 | H19: =Inputs!$B$8*Inputs!$B$16*H6 -> 10171.037 | I19: =Inputs!$B$8*Inputs!$B$16*I6 -> 10171.037 | ... Z19: =Inputs!$B$8*Inputs!$B$16*Z6 -> 7910.8066
A20: Hudson Mercantile invoices issued | B20: =Inputs!$B$8*Inputs!$B$18*B6 -> 6403.9863 | C20: =Inputs!$B$8*Inputs!$B$18*C6 -> 6403.9863 | D20: =Inputs!$B$8*Inputs!$B$18*D6 -> 6403.9863 | E20: =Inputs!$B$8*Inputs!$B$18*E6 -> 6403.9863 | F20: =Inputs!$B$8*Inputs!$B$18*F6 -> 6726.8764 | G20: =Inputs!$B$8*Inputs!$B$18*G6 -> 6780.6914 | H20: =Inputs!$B$8*Inputs!$B$18*H6 -> 6780.6914 | I20: =Inputs!$B$8*Inputs!$B$18*I6 -> 6780.6914 | ... Z20: =Inputs!$B$8*Inputs!$B$18*Z6 -> 5273.8711
A21: Wholesale receipts | N21: =INDEX($B$19:$Z$19,1,(N$4-Inputs!$B$17)+13)+INDEX($B$20:$Z$20,1,(N$4-Inputs!$B$19)+13) -> 17705.139 | O21: =INDEX($B$19:$Z$19,1,(O$4-Inputs!$B$17)+13)+INDEX($B$20:$Z$20,1,(O$4-Inputs!$B$19)+13) -> 19066.892 | P21: =INDEX($B$19:$Z$19,1,(P$4-Inputs!$B$17)+13)+INDEX($B$20:$Z$20,1,(P$4-Inputs!$B$19)+13) -> 25353.889 | Q21: =INDEX($B$19:$Z$19,1,(Q$4-Inputs!$B$17)+13)+INDEX($B$20:$Z$20,1,(Q$4-Inputs!$B$19)+13) -> 25353.889 | R21: =INDEX($B$19:$Z$19,1,(R$4-Inputs!$B$17)+13)+INDEX($B$20:$Z$20,1,(R$4-Inputs!$B$19)+13) -> 25353.889 | S21: =INDEX($B$19:$Z$19,1,(S$4-Inputs!$B$17)+13)+INDEX($B$20:$Z$20,1,(S$4-Inputs!$B$19)+13) -> 47895.36 | T21: =INDEX($B$19:$Z$19,1,(T$4-Inputs!$B$17)+13)+INDEX($B$20:$Z$20,1,(T$4-Inputs!$B$19)+13) -> 25686.139 | U21: =INDEX($B$19:$Z$19,1,(U$4-Inputs!$B$17)+13)+INDEX($B$20:$Z$20,1,(U$4-Inputs!$B$19)+13) -> 25615.945 | ... Z21: =INDEX($B$19:$Z$19,1,(Z$4-Inputs!$B$17)+13)+INDEX($B$20:$Z$20,1,(Z$4-Inputs!$B$19)+13) -> 20292.939
A23: Payroll run this week (1/0) | N23: 0 | O23: 1 | P23: 0 | Q23: 1 | R23: 0 | S23: 1 | T23: 0 | U23: 1 | V23: 0 | W23: 1 | X23: 0 | Y23: 1 | Z23: 0
A24: Payroll | N24: =-N23*Inputs!$B$23 -> 0 | O24: =-O23*Inputs!$B$23 -> -50000 | P24: =-P23*Inputs!$B$23 -> 0 | Q24: =-Q23*Inputs!$B$23 -> -50000 | R24: =-R23*Inputs!$B$23 -> 0 | S24: =-S23*Inputs!$B$23 -> -50000 | T24: =-T23*Inputs!$B$23 -> 0 | U24: =-U23*Inputs!$B$23 -> -50000 | ... Z24: =-Z23*Inputs!$B$23 -> 0
A25: Inventory purchase orders | N25: =-SUMIFS(Bills!$M$2:$M$11,Bills!$C$2:$C$11,"inventory",Bills!$F$2:$F$11,N$4) -> 0 | O25: =-SUMIFS(Bills!$M$2:$M$11,Bills!$C$2:$C$11,"inventory",Bills!$F$2:$F$11,O$4) -> 0 | P25: =-SUMIFS(Bills!$M$2:$M$11,Bills!$C$2:$C$11,"inventory",Bills!$F$2:$F$11,P$4) -> 0 | Q25: =-SUMIFS(Bills!$M$2:$M$11,Bills!$C$2:$C$11,"inventory",Bills!$F$2:$F$11,Q$4) -> -520000 | R25: =-SUMIFS(Bills!$M$2:$M$11,Bills!$C$2:$C$11,"inventory",Bills!$F$2:$F$11,R$4) -> 0 | S25: =-SUMIFS(Bills!$M$2:$M$11,Bills!$C$2:$C$11,"inventory",Bills!$F$2:$F$11,S$4) -> 0 | T25: =-SUMIFS(Bills!$M$2:$M$11,Bills!$C$2:$C$11,"inventory",Bills!$F$2:$F$11,T$4) -> 0 | U25: =-SUMIFS(Bills!$M$2:$M$11,Bills!$C$2:$C$11,"inventory",Bills!$F$2:$F$11,U$4) -> 0 | ... Z25: =-SUMIFS(Bills!$M$2:$M$11,Bills!$C$2:$C$11,"inventory",Bills!$F$2:$F$11,Z$4) -> 0
A26: Freight and duty | N26: =-SUMIFS(Bills!$M$2:$M$11,Bills!$C$2:$C$11,"freight_duty",Bills!$F$2:$F$11,N$4) -> 0 | O26: =-SUMIFS(Bills!$M$2:$M$11,Bills!$C$2:$C$11,"freight_duty",Bills!$F$2:$F$11,O$4) -> 0 | P26: =-SUMIFS(Bills!$M$2:$M$11,Bills!$C$2:$C$11,"freight_duty",Bills!$F$2:$F$11,P$4) -> 0 | Q26: =-SUMIFS(Bills!$M$2:$M$11,Bills!$C$2:$C$11,"freight_duty",Bills!$F$2:$F$11,Q$4) -> -95000 | R26: =-SUMIFS(Bills!$M$2:$M$11,Bills!$C$2:$C$11,"freight_duty",Bills!$F$2:$F$11,R$4) -> 0 | S26: =-SUMIFS(Bills!$M$2:$M$11,Bills!$C$2:$C$11,"freight_duty",Bills!$F$2:$F$11,S$4) -> 0 | T26: =-SUMIFS(Bills!$M$2:$M$11,Bills!$C$2:$C$11,"freight_duty",Bills!$F$2:$F$11,T$4) -> 0 | U26: =-SUMIFS(Bills!$M$2:$M$11,Bills!$C$2:$C$11,"freight_duty",Bills!$F$2:$F$11,U$4) -> 0 | ... Z26: =-SUMIFS(Bills!$M$2:$M$11,Bills!$C$2:$C$11,"freight_duty",Bills!$F$2:$F$11,Z$4) -> 0
A27: 3PL invoices | N27: =-SUMIFS(Bills!$M$2:$M$11,Bills!$C$2:$C$11,"fulfillment_3pl",Bills!$F$2:$F$11,N$4) -> 0 | O27: =-SUMIFS(Bills!$M$2:$M$11,Bills!$C$2:$C$11,"fulfillment_3pl",Bills!$F$2:$F$11,O$4) -> 0 | P27: =-SUMIFS(Bills!$M$2:$M$11,Bills!$C$2:$C$11,"fulfillment_3pl",Bills!$F$2:$F$11,P$4) -> 0 | Q27: =-SUMIFS(Bills!$M$2:$M$11,Bills!$C$2:$C$11,"fulfillment_3pl",Bills!$F$2:$F$11,Q$4) -> 0 | R27: =-SUMIFS(Bills!$M$2:$M$11,Bills!$C$2:$C$11,"fulfillment_3pl",Bills!$F$2:$F$11,R$4) -> 0 | S27: =-SUMIFS(Bills!$M$2:$M$11,Bills!$C$2:$C$11,"fulfillment_3pl",Bills!$F$2:$F$11,S$4) -> 0 | T27: =-SUMIFS(Bills!$M$2:$M$11,Bills!$C$2:$C$11,"fulfillment_3pl",Bills!$F$2:$F$11,T$4) -> -69511.056 | U27: =-SUMIFS(Bills!$M$2:$M$11,Bills!$C$2:$C$11,"fulfillment_3pl",Bills!$F$2:$F$11,U$4) -> 0 | ... Z27: =-SUMIFS(Bills!$M$2:$M$11,Bills!$C$2:$C$11,"fulfillment_3pl",Bills!$F$2:$F$11,Z$4) -> 0
A28: Packaging and software bills | N28: =-SUMIFS(Bills!$M$2:$M$11,Bills!$C$2:$C$11,"other_ap",Bills!$F$2:$F$11,N$4) -> 0 | O28: =-SUMIFS(Bills!$M$2:$M$11,Bills!$C$2:$C$11,"other_ap",Bills!$F$2:$F$11,O$4) -> 0 | P28: =-SUMIFS(Bills!$M$2:$M$11,Bills!$C$2:$C$11,"other_ap",Bills!$F$2:$F$11,P$4) -> 0 | Q28: =-SUMIFS(Bills!$M$2:$M$11,Bills!$C$2:$C$11,"other_ap",Bills!$F$2:$F$11,Q$4) -> 0 | R28: =-SUMIFS(Bills!$M$2:$M$11,Bills!$C$2:$C$11,"other_ap",Bills!$F$2:$F$11,R$4) -> 0 | S28: =-SUMIFS(Bills!$M$2:$M$11,Bills!$C$2:$C$11,"other_ap",Bills!$F$2:$F$11,S$4) -> -5560.8845 | T28: =-SUMIFS(Bills!$M$2:$M$11,Bills!$C$2:$C$11,"other_ap",Bills!$F$2:$F$11,T$4) -> 0 | U28: =-SUMIFS(Bills!$M$2:$M$11,Bills!$C$2:$C$11,"other_ap",Bills!$F$2:$F$11,U$4) -> 0 | ... Z28: =-SUMIFS(Bills!$M$2:$M$11,Bills!$C$2:$C$11,"other_ap",Bills!$F$2:$F$11,Z$4) -> 0
A29: Card autopay | N29: =-SUMIFS(Calendar!$I$2:$I$176,Calendar!$B$2:$B$176,N$4) -> 0 | O29: =-SUMIFS(Calendar!$I$2:$I$176,Calendar!$B$2:$B$176,O$4) -> 0 | P29: =-SUMIFS(Calendar!$I$2:$I$176,Calendar!$B$2:$B$176,P$4) -> 0 | Q29: =-SUMIFS(Calendar!$I$2:$I$176,Calendar!$B$2:$B$176,Q$4) -> -134735.91 | R29: =-SUMIFS(Calendar!$I$2:$I$176,Calendar!$B$2:$B$176,R$4) -> 0 | S29: =-SUMIFS(Calendar!$I$2:$I$176,Calendar!$B$2:$B$176,S$4) -> 0 | T29: =-SUMIFS(Calendar!$I$2:$I$176,Calendar!$B$2:$B$176,T$4) -> 0 | U29: =-SUMIFS(Calendar!$I$2:$I$176,Calendar!$B$2:$B$176,U$4) -> 0 | ... Z29: =-SUMIFS(Calendar!$I$2:$I$176,Calendar!$B$2:$B$176,Z$4) -> -200021.2
A30: Fixed costs | N30: =-SUMIFS(Calendar!$J$2:$J$176,Calendar!$B$2:$B$176,N$4) -> -24000 | O30: =-SUMIFS(Calendar!$J$2:$J$176,Calendar!$B$2:$B$176,O$4) -> 0 | P30: =-SUMIFS(Calendar!$J$2:$J$176,Calendar!$B$2:$B$176,P$4) -> 0 | Q30: =-SUMIFS(Calendar!$J$2:$J$176,Calendar!$B$2:$B$176,Q$4) -> 0 | R30: =-SUMIFS(Calendar!$J$2:$J$176,Calendar!$B$2:$B$176,R$4) -> 0 | S30: =-SUMIFS(Calendar!$J$2:$J$176,Calendar!$B$2:$B$176,S$4) -> -24000 | T30: =-SUMIFS(Calendar!$J$2:$J$176,Calendar!$B$2:$B$176,T$4) -> 0 | U30: =-SUMIFS(Calendar!$J$2:$J$176,Calendar!$B$2:$B$176,U$4) -> 0 | ... Z30: =-SUMIFS(Calendar!$J$2:$J$176,Calendar!$B$2:$B$176,Z$4) -> 0
A31: Sales tax | N31: =-SUMIFS(Calendar!$L$2:$L$176,Calendar!$B$2:$B$176,N$4) -> 0 | O31: =-SUMIFS(Calendar!$L$2:$L$176,Calendar!$B$2:$B$176,O$4) -> 0 | P31: =-SUMIFS(Calendar!$L$2:$L$176,Calendar!$B$2:$B$176,P$4) -> 0 | Q31: =-SUMIFS(Calendar!$L$2:$L$176,Calendar!$B$2:$B$176,Q$4) -> -22243.538 | R31: =-SUMIFS(Calendar!$L$2:$L$176,Calendar!$B$2:$B$176,R$4) -> 0 | S31: =-SUMIFS(Calendar!$L$2:$L$176,Calendar!$B$2:$B$176,S$4) -> 0 | T31: =-SUMIFS(Calendar!$L$2:$L$176,Calendar!$B$2:$B$176,T$4) -> 0 | U31: =-SUMIFS(Calendar!$L$2:$L$176,Calendar!$B$2:$B$176,U$4) -> -45204.609 | ... Z31: =-SUMIFS(Calendar!$L$2:$L$176,Calendar!$B$2:$B$176,Z$4) -> -35589.661
A32: Credit line interest | N32: =-SUMIFS(Calendar!$K$2:$K$176,Calendar!$B$2:$B$176,N$4) -> -3666.6667 | O32: =-SUMIFS(Calendar!$K$2:$K$176,Calendar!$B$2:$B$176,O$4) -> 0 | P32: =-SUMIFS(Calendar!$K$2:$K$176,Calendar!$B$2:$B$176,P$4) -> 0 | Q32: =-SUMIFS(Calendar!$K$2:$K$176,Calendar!$B$2:$B$176,Q$4) -> 0 | R32: =-SUMIFS(Calendar!$K$2:$K$176,Calendar!$B$2:$B$176,R$4) -> 0 | S32: =-SUMIFS(Calendar!$K$2:$K$176,Calendar!$B$2:$B$176,S$4) -> -3666.6667 | T32: =-SUMIFS(Calendar!$K$2:$K$176,Calendar!$B$2:$B$176,T$4) -> 0 | U32: =-SUMIFS(Calendar!$K$2:$K$176,Calendar!$B$2:$B$176,U$4) -> 0 | ... Z32: =-SUMIFS(Calendar!$K$2:$K$176,Calendar!$B$2:$B$176,Z$4) -> 0
A33: Bank fees and other | N33: =-Inputs!$B$26 -> -160.9375 | O33: =-Inputs!$B$26 -> -160.9375 | P33: =-Inputs!$B$26 -> -160.9375 | Q33: =-Inputs!$B$26 -> -160.9375 | R33: =-Inputs!$B$26 -> -160.9375 | S33: =-Inputs!$B$26 -> -160.9375 | T33: =-Inputs!$B$26 -> -160.9375 | U33: =-Inputs!$B$26 -> -160.9375 | ... Z33: =-Inputs!$B$26 -> -160.9375
A35: Net cash flow | N35: =N14+N17+N21+SUM(N24:N33) -> 128959.74 | O35: =O14+O17+O21+SUM(O24:O33) -> 138322.39 | P35: =P14+P17+P21+SUM(P24:P33) -> 236619.49 | Q35: =Q14+Q17+Q21+SUM(Q24:Q33) -> -609403.56 | R35: =R14+R17+R21+SUM(R24:R33) -> 400809.94 | S35: =S14+S17+S21+SUM(S24:S33) -> 212587.21 | T35: =T14+T17+T21+SUM(T24:T33) -> 184403.66 | U35: =U14+U17+U21+SUM(U24:U33) -> 112676.11 | ... Z35: =Z14+Z17+Z21+SUM(Z24:Z33) -> -125998.85
A36: Opening cash | N36: =Inputs!$B$27 -> 300000 | O36: =N37 -> 428959.74 | P36: =O37 -> 567282.13 | Q36: =P37 -> 803901.62 | R36: =Q37 -> 194498.07 | S36: =R37 -> 595308.01 | T36: =S37 -> 807895.22 | U36: =T37 -> 992298.88 | V36: =U37 -> 1104975 | ... Z36: =Y37 -> 1015386.7
A37: Closing cash | N37: =N36+N35 -> 428959.74 | O37: =O36+O35 -> 567282.13 | P37: =P36+P35 -> 803901.62 | Q37: =Q36+Q35 -> 194498.07 | R37: =R36+R35 -> 595308.01 | S37: =S36+S35 -> 807895.22 | T37: =T36+T35 -> 992298.88 | U37: =U36+U35 -> 1104975 | ... Z37: =Z36+Z35 -> 889387.84
A38: Cash buffer | N38: =Inputs!$B$28 -> 300000 | O38: =Inputs!$B$28 -> 300000 | P38: =Inputs!$B$28 -> 300000 | Q38: =Inputs!$B$28 -> 300000 | R38: =Inputs!$B$28 -> 300000 | S38: =Inputs!$B$28 -> 300000 | T38: =Inputs!$B$28 -> 300000 | U38: =Inputs!$B$28 -> 300000 | ... Z38: =Inputs!$B$28 -> 300000
A39: Under buffer by | N39: =MAX(0,N38-N37) -> 0 | O39: =MAX(0,O38-O37) -> 0 | P39: =MAX(0,P38-P37) -> 0 | Q39: =MAX(0,Q38-Q37) -> 105501.93 | R39: =MAX(0,R38-R37) -> 0 | S39: =MAX(0,S38-S37) -> 0 | T39: =MAX(0,T38-T37) -> 0 | U39: =MAX(0,U38-U37) -> 0 | ... Z39: =MAX(0,Z38-Z37) -> 0
A41: Watch: ad spend charged to the card (paid with next month's autopay) | N41: =-N8*Inputs!$B$20 -> -30164.484 | O41: =-O8*Inputs!$B$20 -> -45401.151 | P41: =-P8*Inputs!$B$20 -> -45401.151 | Q41: =-Q8*Inputs!$B$20 -> -45401.151 | R41: =-R8*Inputs!$B$20 -> -99450.14 | S41: =-S8*Inputs!$B$20 -> -44371.646 | T41: =-T8*Inputs!$B$20 -> -44200.062 | U41: =-U8*Inputs!$B$20 -> -44200.062 | ... Z41: =-Z8*Inputs!$B$20 -> -19337.527
A43: Summary
A44: Low point (closing cash) | B44: =MIN(N37:Z37) -> 194498.07
A45: Low point week | B45: =INDEX(N5:Z5,1,MATCH(B44,N37:Z37,0)) -> 46342
A46: Gap to buffer | B46: =MAX(0,Inputs!$B$28-B44) -> 105501.93
A47: Credit draw to hold the buffer | B47: =CEILING(B46,Inputs!$B$32) -> 125000
A48: Credit headroom | B48: =Inputs!$B$29-Inputs!$B$30 -> 1100000
...

Sheet Calendar
A1: Date | B1: Week | C1: Month key | D1: Sales intensity | E1: Prior month key | F1: Share of week | G1: Shopify gross | H1: Card spend | I1: Card autopay due | J1: Fixed costs due | K1: Interest due | L1: Sales tax due
A2: 46237 | B2: =INT((A2-Inputs!$B$5)/7) -> -12 | C2: =YEAR(A2)*100+MONTH(A2) -> 202608 | D2: =IF(AND(A2>=Inputs!$B$33,A2<=Inputs!$B$34),INDEX(Inputs!$B$38:$B$49,11)*30*Inputs!$B$35/7,IF(MONTH(A2)=11,INDEX(Inputs!$B$38:$B$49,11)*30*(1-Inputs!$B$35)/23,INDEX(Inputs!$B$38:$B$49,MONTH(A2)))) -> 0.85 | E2: =IF(MONTH(A2)=1,(YEAR(A2)-1)*100+12,YEAR(A2)*100+MONTH(A2)-1) -> 202607 | F2: =D2/SUMIFS($D$2:$D$176,$B$2:$B$176,B2) -> 0.14285714 | G2: =INDEX(Forecast!$B$8:$Z$8,1,(B2)+13)*F2 -> 15247.586 | H2: =IF(B2>=0,(INDEX(Forecast!$B$8:$Z$8,1,(B2)+13)*Inputs!$B$20+Inputs!$B$22)/7,IF(C2=202610,(Inputs!$B$21+Inputs!$B$22)/7,0)) -> 0 | I2: =IF(DAY(A2)=22,SUMIFS($H$2:$H$176,$C$2:$C$176,E2),0) -> 0 | J2: =IF(DAY(A2)=1,Inputs!$B$24,0) -> 0 | K2: =IF(DAY(A2)=1,Inputs!$B$30*Inputs!$B$31/12,0) -> 0 | L2: =IF(DAY(A2)=20,Inputs!$B$25*SUMIFS($G$2:$G$176,$C$2:$C$176,E2),0) -> 0
A3: 46238 | B3: =INT((A3-Inputs!$B$5)/7) -> -12 | C3: =YEAR(A3)*100+MONTH(A3) -> 202608 | D3: =IF(AND(A3>=Inputs!$B$33,A3<=Inputs!$B$34),INDEX(Inputs!$B$38:$B$49,11)*30*Inputs!$B$35/7,IF(MONTH(A3)=11,INDEX(Inputs!$B$38:$B$49,11)*30*(1-Inputs!$B$35)/23,INDEX(Inputs!$B$38:$B$49,MONTH(A3)))) -> 0.85 | E3: =IF(MONTH(A3)=1,(YEAR(A3)-1)*100+12,YEAR(A3)*100+MONTH(A3)-1) -> 202607 | F3: =D3/SUMIFS($D$2:$D$176,$B$2:$B$176,B3) -> 0.14285714 | G3: =INDEX(Forecast!$B$8:$Z$8,1,(B3)+13)*F3 -> 15247.586 | H3: =IF(B3>=0,(INDEX(Forecast!$B$8:$Z$8,1,(B3)+13)*Inputs!$B$20+Inputs!$B$22)/7,IF(C3=202610,(Inputs!$B$21+Inputs!$B$22)/7,0)) -> 0 | I3: =IF(DAY(A3)=22,SUMIFS($H$2:$H$176,$C$2:$C$176,E3),0) -> 0 | J3: =IF(DAY(A3)=1,Inputs!$B$24,0) -> 0 | K3: =IF(DAY(A3)=1,Inputs!$B$30*Inputs!$B$31/12,0) -> 0 | L3: =IF(DAY(A3)=20,Inputs!$B$25*SUMIFS($G$2:$G$176,$C$2:$C$176,E3),0) -> 0
A4: 46239 | B4: =INT((A4-Inputs!$B$5)/7) -> -12 | C4: =YEAR(A4)*100+MONTH(A4) -> 202608 | D4: =IF(AND(A4>=Inputs!$B$33,A4<=Inputs!$B$34),INDEX(Inputs!$B$38:$B$49,11)*30*Inputs!$B$35/7,IF(MONTH(A4)=11,INDEX(Inputs!$B$38:$B$49,11)*30*(1-Inputs!$B$35)/23,INDEX(Inputs!$B$38:$B$49,MONTH(A4)))) -> 0.85 | E4: =IF(MONTH(A4)=1,(YEAR(A4)-1)*100+12,YEAR(A4)*100+MONTH(A4)-1) -> 202607 | F4: =D4/SUMIFS($D$2:$D$176,$B$2:$B$176,B4) -> 0.14285714 | G4: =INDEX(Forecast!$B$8:$Z$8,1,(B4)+13)*F4 -> 15247.586 | H4: =IF(B4>=0,(INDEX(Forecast!$B$8:$Z$8,1,(B4)+13)*Inputs!$B$20+Inputs!$B$22)/7,IF(C4=202610,(Inputs!$B$21+Inputs!$B$22)/7,0)) -> 0 | I4: =IF(DAY(A4)=22,SUMIFS($H$2:$H$176,$C$2:$C$176,E4),0) -> 0 | J4: =IF(DAY(A4)=1,Inputs!$B$24,0) -> 0 | K4: =IF(DAY(A4)=1,Inputs!$B$30*Inputs!$B$31/12,0) -> 0 | L4: =IF(DAY(A4)=20,Inputs!$B$25*SUMIFS($G$2:$G$176,$C$2:$C$176,E4),0) -> 0
A5: 46240 | B5: =INT((A5-Inputs!$B$5)/7) -> -12 | C5: =YEAR(A5)*100+MONTH(A5) -> 202608 | D5: =IF(AND(A5>=Inputs!$B$33,A5<=Inputs!$B$34),INDEX(Inputs!$B$38:$B$49,11)*30*Inputs!$B$35/7,IF(MONTH(A5)=11,INDEX(Inputs!$B$38:$B$49,11)*30*(1-Inputs!$B$35)/23,INDEX(Inputs!$B$38:$B$49,MONTH(A5)))) -> 0.85 | E5: =IF(MONTH(A5)=1,(YEAR(A5)-1)*100+12,YEAR(A5)*100+MONTH(A5)-1) -> 202607 | F5: =D5/SUMIFS($D$2:$D$176,$B$2:$B$176,B5) -> 0.14285714 | G5: =INDEX(Forecast!$B$8:$Z$8,1,(B5)+13)*F5 -> 15247.586 | H5: =IF(B5>=0,(INDEX(Forecast!$B$8:$Z$8,1,(B5)+13)*Inputs!$B$20+Inputs!$B$22)/7,IF(C5=202610,(Inputs!$B$21+Inputs!$B$22)/7,0)) -> 0 | I5: =IF(DAY(A5)=22,SUMIFS($H$2:$H$176,$C$2:$C$176,E5),0) -> 0 | J5: =IF(DAY(A5)=1,Inputs!$B$24,0) -> 0 | K5: =IF(DAY(A5)=1,Inputs!$B$30*Inputs!$B$31/12,0) -> 0 | L5: =IF(DAY(A5)=20,Inputs!$B$25*SUMIFS($G$2:$G$176,$C$2:$C$176,E5),0) -> 0
A6: 46241 | B6: =INT((A6-Inputs!$B$5)/7) -> -12 | C6: =YEAR(A6)*100+MONTH(A6) -> 202608 | D6: =IF(AND(A6>=Inputs!$B$33,A6<=Inputs!$B$34),INDEX(Inputs!$B$38:$B$49,11)*30*Inputs!$B$35/7,IF(MONTH(A6)=11,INDEX(Inputs!$B$38:$B$49,11)*30*(1-Inputs!$B$35)/23,INDEX(Inputs!$B$38:$B$49,MONTH(A6)))) -> 0.85 | E6: =IF(MONTH(A6)=1,(YEAR(A6)-1)*100+12,YEAR(A6)*100+MONTH(A6)-1) -> 202607 | F6: =D6/SUMIFS($D$2:$D$176,$B$2:$B$176,B6) -> 0.14285714 | G6: =INDEX(Forecast!$B$8:$Z$8,1,(B6)+13)*F6 -> 15247.586 | H6: =IF(B6>=0,(INDEX(Forecast!$B$8:$Z$8,1,(B6)+13)*Inputs!$B$20+Inputs!$B$22)/7,IF(C6=202610,(Inputs!$B$21+Inputs!$B$22)/7,0)) -> 0 | I6: =IF(DAY(A6)=22,SUMIFS($H$2:$H$176,$C$2:$C$176,E6),0) -> 0 | J6: =IF(DAY(A6)=1,Inputs!$B$24,0) -> 0 | K6: =IF(DAY(A6)=1,Inputs!$B$30*Inputs!$B$31/12,0) -> 0 | L6: =IF(DAY(A6)=20,Inputs!$B$25*SUMIFS($G$2:$G$176,$C$2:$C$176,E6),0) -> 0
A7: 46242 | B7: =INT((A7-Inputs!$B$5)/7) -> -12 | C7: =YEAR(A7)*100+MONTH(A7) -> 202608 | D7: =IF(AND(A7>=Inputs!$B$33,A7<=Inputs!$B$34),INDEX(Inputs!$B$38:$B$49,11)*30*Inputs!$B$35/7,IF(MONTH(A7)=11,INDEX(Inputs!$B$38:$B$49,11)*30*(1-Inputs!$B$35)/23,INDEX(Inputs!$B$38:$B$49,MONTH(A7)))) -> 0.85 | E7: =IF(MONTH(A7)=1,(YEAR(A7)-1)*100+12,YEAR(A7)*100+MONTH(A7)-1) -> 202607 | F7: =D7/SUMIFS($D$2:$D$176,$B$2:$B$176,B7) -> 0.14285714 | G7: =INDEX(Forecast!$B$8:$Z$8,1,(B7)+13)*F7 -> 15247.586 | H7: =IF(B7>=0,(INDEX(Forecast!$B$8:$Z$8,1,(B7)+13)*Inputs!$B$20+Inputs!$B$22)/7,IF(C7=202610,(Inputs!$B$21+Inputs!$B$22)/7,0)) -> 0 | I7: =IF(DAY(A7)=22,SUMIFS($H$2:$H$176,$C$2:$C$176,E7),0) -> 0 | J7: =IF(DAY(A7)=1,Inputs!$B$24,0) -> 0 | K7: =IF(DAY(A7)=1,Inputs!$B$30*Inputs!$B$31/12,0) -> 0 | L7: =IF(DAY(A7)=20,Inputs!$B$25*SUMIFS($G$2:$G$176,$C$2:$C$176,E7),0) -> 0
A8: 46243 | B8: =INT((A8-Inputs!$B$5)/7) -> -12 | C8: =YEAR(A8)*100+MONTH(A8) -> 202608 | D8: =IF(AND(A8>=Inputs!$B$33,A8<=Inputs!$B$34),INDEX(Inputs!$B$38:$B$49,11)*30*Inputs!$B$35/7,IF(MONTH(A8)=11,INDEX(Inputs!$B$38:$B$49,11)*30*(1-Inputs!$B$35)/23,INDEX(Inputs!$B$38:$B$49,MONTH(A8)))) -> 0.85 | E8: =IF(MONTH(A8)=1,(YEAR(A8)-1)*100+12,YEAR(A8)*100+MONTH(A8)-1) -> 202607 | F8: =D8/SUMIFS($D$2:$D$176,$B$2:$B$176,B8) -> 0.14285714 | G8: =INDEX(Forecast!$B$8:$Z$8,1,(B8)+13)*F8 -> 15247.586 | H8: =IF(B8>=0,(INDEX(Forecast!$B$8:$Z$8,1,(B8)+13)*Inputs!$B$20+Inputs!$B$22)/7,IF(C8=202610,(Inputs!$B$21+Inputs!$B$22)/7,0)) -> 0 | I8: =IF(DAY(A8)=22,SUMIFS($H$2:$H$176,$C$2:$C$176,E8),0) -> 0 | J8: =IF(DAY(A8)=1,Inputs!$B$24,0) -> 0 | K8: =IF(DAY(A8)=1,Inputs!$B$30*Inputs!$B$31/12,0) -> 0 | L8: =IF(DAY(A8)=20,Inputs!$B$25*SUMIFS($G$2:$G$176,$C$2:$C$176,E8),0) -> 0
A9: 46244 | B9: =INT((A9-Inputs!$B$5)/7) -> -11 | C9: =YEAR(A9)*100+MONTH(A9) -> 202608 | D9: =IF(AND(A9>=Inputs!$B$33,A9<=Inputs!$B$34),INDEX(Inputs!$B$38:$B$49,11)*30*Inputs!$B$35/7,IF(MONTH(A9)=11,INDEX(Inputs!$B$38:$B$49,11)*30*(1-Inputs!$B$35)/23,INDEX(Inputs!$B$38:$B$49,MONTH(A9)))) -> 0.85 | E9: =IF(MONTH(A9)=1,(YEAR(A9)-1)*100+12,YEAR(A9)*100+MONTH(A9)-1) -> 202607 | F9: =D9/SUMIFS($D$2:$D$176,$B$2:$B$176,B9) -> 0.14285714 | G9: =INDEX(Forecast!$B$8:$Z$8,1,(B9)+13)*F9 -> 15247.586 | H9: =IF(B9>=0,(INDEX(Forecast!$B$8:$Z$8,1,(B9)+13)*Inputs!$B$20+Inputs!$B$22)/7,IF(C9=202610,(Inputs!$B$21+Inputs!$B$22)/7,0)) -> 0 | I9: =IF(DAY(A9)=22,SUMIFS($H$2:$H$176,$C$2:$C$176,E9),0) -> 0 | J9: =IF(DAY(A9)=1,Inputs!$B$24,0) -> 0 | K9: =IF(DAY(A9)=1,Inputs!$B$30*Inputs!$B$31/12,0) -> 0 | L9: =IF(DAY(A9)=20,Inputs!$B$25*SUMIFS($G$2:$G$176,$C$2:$C$176,E9),0) -> 0
A10: 46245 | B10: =INT((A10-Inputs!$B$5)/7) -> -11 | C10: =YEAR(A10)*100+MONTH(A10) -> 202608 | D10: =IF(AND(A10>=Inputs!$B$33,A10<=Inputs!$B$34),INDEX(Inputs!$B$38:$B$49,11)*30*Inputs!$B$35/7,IF(MONTH(A10)=11,INDEX(Inputs!$B$38:$B$49,11)*30*(1-Inputs!$B$35)/23,INDEX(Inputs!$B$38:$B$49,MONTH(A10)))) -> 0.85 | E10: =IF(MONTH(A10)=1,(YEAR(A10)-1)*100+12,YEAR(A10)*100+MONTH(A10)-1) -> 202607 | F10: =D10/SUMIFS($D$2:$D$176,$B$2:$B$176,B10) -> 0.14285714 | G10: =INDEX(Forecast!$B$8:$Z$8,1,(B10)+13)*F10 -> 15247.586 | H10: =IF(B10>=0,(INDEX(Forecast!$B$8:$Z$8,1,(B10)+13)*Inputs!$B$20+Inputs!$B$22)/7,IF(C10=202610,(Inputs!$B$21+Inputs!$B$22)/7,0)) -> 0 | I10: =IF(DAY(A10)=22,SUMIFS($H$2:$H$176,$C$2:$C$176,E10),0) -> 0 | J10: =IF(DAY(A10)=1,Inputs!$B$24,0) -> 0 | K10: =IF(DAY(A10)=1,Inputs!$B$30*Inputs!$B$31/12,0) -> 0 | L10: =IF(DAY(A10)=20,Inputs!$B$25*SUMIFS($G$2:$G$176,$C$2:$C$176,E10),0) -> 0
A11: 46246 | B11: =INT((A11-Inputs!$B$5)/7) -> -11 | C11: =YEAR(A11)*100+MONTH(A11) -> 202608 | D11: =IF(AND(A11>=Inputs!$B$33,A11<=Inputs!$B$34),INDEX(Inputs!$B$38:$B$49,11)*30*Inputs!$B$35/7,IF(MONTH(A11)=11,INDEX(Inputs!$B$38:$B$49,11)*30*(1-Inputs!$B$35)/23,INDEX(Inputs!$B$38:$B$49,MONTH(A11)))) -> 0.85 | E11: =IF(MONTH(A11)=1,(YEAR(A11)-1)*100+12,YEAR(A11)*100+MONTH(A11)-1) -> 202607 | F11: =D11/SUMIFS($D$2:$D$176,$B$2:$B$176,B11) -> 0.14285714 | G11: =INDEX(Forecast!$B$8:$Z$8,1,(B11)+13)*F11 -> 15247.586 | H11: =IF(B11>=0,(INDEX(Forecast!$B$8:$Z$8,1,(B11)+13)*Inputs!$B$20+Inputs!$B$22)/7,IF(C11=202610,(Inputs!$B$21+Inputs!$B$22)/7,0)) -> 0 | I11: =IF(DAY(A11)=22,SUMIFS($H$2:$H$176,$C$2:$C$176,E11),0) -> 0 | J11: =IF(DAY(A11)=1,Inputs!$B$24,0) -> 0 | K11: =IF(DAY(A11)=1,Inputs!$B$30*Inputs!$B$31/12,0) -> 0 | L11: =IF(DAY(A11)=20,Inputs!$B$25*SUMIFS($G$2:$G$176,$C$2:$C$176,E11),0) -> 0
A12: 46247 | B12: =INT((A12-Inputs!$B$5)/7) -> -11 | C12: =YEAR(A12)*100+MONTH(A12) -> 202608 | D12: =IF(AND(A12>=Inputs!$B$33,A12<=Inputs!$B$34),INDEX(Inputs!$B$38:$B$49,11)*30*Inputs!$B$35/7,IF(MONTH(A12)=11,INDEX(Inputs!$B$38:$B$49,11)*30*(1-Inputs!$B$35)/23,INDEX(Inputs!$B$38:$B$49,MONTH(A12)))) -> 0.85 | E12: =IF(MONTH(A12)=1,(YEAR(A12)-1)*100+12,YEAR(A12)*100+MONTH(A12)-1) -> 202607 | F12: =D12/SUMIFS($D$2:$D$176,$B$2:$B$176,B12) -> 0.14285714 | G12: =INDEX(Forecast!$B$8:$Z$8,1,(B12)+13)*F12 -> 15247.586 | H12: =IF(B12>=0,(INDEX(Forecast!$B$8:$Z$8,1,(B12)+13)*Inputs!$B$20+Inputs!$B$22)/7,IF(C12=202610,(Inputs!$B$21+Inputs!$B$22)/7,0)) -> 0 | I12: =IF(DAY(A12)=22,SUMIFS($H$2:$H$176,$C$2:$C$176,E12),0) -> 0 | J12: =IF(DAY(A12)=1,Inputs!$B$24,0) -> 0 | K12: =IF(DAY(A12)=1,Inputs!$B$30*Inputs!$B$31/12,0) -> 0 | L12: =IF(DAY(A12)=20,Inputs!$B$25*SUMIFS($G$2:$G$176,$C$2:$C$176,E12),0) -> 0
A13: 46248 | B13: =INT((A13-Inputs!$B$5)/7) -> -11 | C13: =YEAR(A13)*100+MONTH(A13) -> 202608 | D13: =IF(AND(A13>=Inputs!$B$33,A13<=Inputs!$B$34),INDEX(Inputs!$B$38:$B$49,11)*30*Inputs!$B$35/7,IF(MONTH(A13)=11,INDEX(Inputs!$B$38:$B$49,11)*30*(1-Inputs!$B$35)/23,INDEX(Inputs!$B$38:$B$49,MONTH(A13)))) -> 0.85 | E13: =IF(MONTH(A13)=1,(YEAR(A13)-1)*100+12,YEAR(A13)*100+MONTH(A13)-1) -> 202607 | F13: =D13/SUMIFS($D$2:$D$176,$B$2:$B$176,B13) -> 0.14285714 | G13: =INDEX(Forecast!$B$8:$Z$8,1,(B13)+13)*F13 -> 15247.586 | H13: =IF(B13>=0,(INDEX(Forecast!$B$8:$Z$8,1,(B13)+13)*Inputs!$B$20+Inputs!$B$22)/7,IF(C13=202610,(Inputs!$B$21+Inputs!$B$22)/7,0)) -> 0 | I13: =IF(DAY(A13)=22,SUMIFS($H$2:$H$176,$C$2:$C$176,E13),0) -> 0 | J13: =IF(DAY(A13)=1,Inputs!$B$24,0) -> 0 | K13: =IF(DAY(A13)=1,Inputs!$B$30*Inputs!$B$31/12,0) -> 0 | L13: =IF(DAY(A13)=20,Inputs!$B$25*SUMIFS($G$2:$G$176,$C$2:$C$176,E13),0) -> 0
... A176: 46411 | B176: =INT((A176-Inputs!$B$5)/7) -> 12 | C176: =YEAR(A176)*100+MONTH(A176) -> 202701 | D176: =IF(AND(A176>=Inputs!$B$33,A176<=Inputs!$B$34),INDEX(Inputs!$B$38:$B$49,11)*30*Inputs!$B$35/7,IF(MONTH(A176)=11,INDEX(Inputs!$B$38:$B$49,11)*30*(1-Inputs!$B$35)/23,INDEX(Inputs!$B$38:$B$49,MONTH(A176)))) -> 0.7 | E176: =IF(MONTH(A176)=1,(YEAR(A176)-1)*100+12,YEAR(A176)*100+MONTH(A176)-1) -> 202612 | F176: =D176/SUMIFS($D$2:$D$176,$B$2:$B$176,B176) -> 0.14285714 | G176: =INDEX(Forecast!$B$8:$Z$8,1,(B176)+13)*F176 -> 12556.836 | H176: =IF(B176>=0,(INDEX(Forecast!$B$8:$Z$8,1,(B176)+13)*Inputs!$B$20+Inputs!$B$22)/7,IF(C176=202610,(Inputs!$B$21+Inputs!$B$22)/7,0)) -> 3092.1742 | I176: =IF(DAY(A176)=22,SUMIFS($H$2:$H$176,$C$2:$C$176,E176),0) -> 0 | J176: =IF(DAY(A176)=1,Inputs!$B$24,0) -> 0 | K176: =IF(DAY(A176)=1,Inputs!$B$30*Inputs!$B$31/12,0) -> 0 | L176: =IF(DAY(A176)=20,Inputs!$B$25*SUMIFS($G$2:$G$176,$C$2:$C$176,E176),0) -> 0

Sheet Bills
A1: Bill | B1: Vendor | C1: Cash line | D1: Issue week | E1: Due week | F1: Pay week | G1: Priced on month | H1: Priced on sales | I1: Rate | J1: Amount | K1: Early-pay discount | L1: Take discount (1/0) | M1: Cash paid | N1: Discount deadline week | O1: Criticality
A2: PO-BFCM-BAL | B2: Kestrel Knitworks Ltd | C2: inventory | D2: 1 | E2: 3 | F2: =E2 -> 3 | J2: 520000 | K2: 0 | L2: 0 | M2: =J2*(1-K2*L2) -> 520000 | N2: =IF(K2>0,D2+1,"-") -> - | O2: critical
A3: PO-SPRING-DEP | B3: Halden Textile Co | C3: inventory | D3: 8 | E3: 10 | F3: =E3 -> 10 | J3: 200000 | K3: 0 | L3: 0 | M3: =J3*(1-K3*L3) -> 200000 | N3: =IF(K3>0,D3+1,"-") -> - | O3: critical
A4: FRT-BFCM | B4: Harborline Freight | C4: freight_duty | D4: 1 | E4: 3 | F4: =E4 -> 3 | J4: 95000 | K4: 0 | L4: 0 | M4: =J4*(1-K4*L4) -> 95000 | N4: =IF(K4>0,D4+1,"-") -> - | O4: high
A5: TPL-202611 | B5: ShipNest 3PL | C5: fulfillment_3pl | D5: =INT((DATE(2026,11,10)-Inputs!$B$5)/7) -> 2 | E5: =D5+4 -> 6 | F5: =E5 -> 6 | G5: 202610 | H5: =SUMIFS(Calendar!$G$2:$G$176,Calendar!$C$2:$C$176,G5) -> 556088.45 | I5: 0.125 | J5: =H5*I5 -> 69511.056 | K5: 0.02 | L5: 0 | M5: =J5*(1-K5*L5) -> 69511.056 | N5: =IF(K5>0,D5+1,"-") -> 3 | O5: high
A6: TPL-202612 | B6: ShipNest 3PL | C6: fulfillment_3pl | D6: =INT((DATE(2026,12,10)-Inputs!$B$5)/7) -> 6 | E6: =D6+4 -> 10 | F6: =E6 -> 10 | G6: 202611 | H6: =SUMIFS(Calendar!$G$2:$G$176,Calendar!$C$2:$C$176,G6) -> 1130115.2 | I6: 0.125 | J6: =H6*I6 -> 141264.4 | K6: 0.02 | L6: 0 | M6: =J6*(1-K6*L6) -> 141264.4 | N6: =IF(K6>0,D6+1,"-") -> 7 | O6: high
A7: TPL-202701 | B7: ShipNest 3PL | C7: fulfillment_3pl | D7: =INT((DATE(2027,1,10)-Inputs!$B$5)/7) -> 10 | E7: =D7+4 -> 14 | F7: =E7 -> 14 | G7: 202612 | H7: =SUMIFS(Calendar!$G$2:$G$176,Calendar!$C$2:$C$176,G7) -> 889741.51 | I7: 0.125 | J7: =H7*I7 -> 111217.69 | K7: 0.02 | L7: 0 | M7: =J7*(1-K7*L7) -> 111217.69 | N7: =IF(K7>0,D7+1,"-") -> 11 | O7: high
A8: PKG-202611 | B8: Noble Box Co | C8: other_ap | D8: =INT((DATE(2026,11,5)-Inputs!$B$5)/7) -> 1 | E8: =D8+4 -> 5 | F8: =E8 -> 5 | G8: 202610 | H8: =SUMIFS(Calendar!$G$2:$G$176,Calendar!$C$2:$C$176,G8) -> 556088.45 | I8: 0.01 | J8: =H8*I8 -> 5560.8845 | K8: 0.01 | L8: 0 | M8: =J8*(1-K8*L8) -> 5560.8845 | N8: =IF(K8>0,D8+1,"-") -> 2 | O8: normal
A9: PKG-202612 | B9: Noble Box Co | C9: other_ap | D9: =INT((DATE(2026,12,5)-Inputs!$B$5)/7) -> 5 | E9: =D9+4 -> 9 | F9: =E9 -> 9 | G9: 202611 | H9: =SUMIFS(Calendar!$G$2:$G$176,Calendar!$C$2:$C$176,G9) -> 1130115.2 | I9: 0.01 | J9: =H9*I9 -> 11301.152 | K9: 0.01 | L9: 0 | M9: =J9*(1-K9*L9) -> 11301.152 | N9: =IF(K9>0,D9+1,"-") -> 6 | O9: normal
A10: PKG-202701 | B10: Noble Box Co | C10: other_ap | D10: =INT((DATE(2027,1,5)-Inputs!$B$5)/7) -> 10 | E10: =D10+4 -> 14 | F10: =E10 -> 14 | G10: 202612 | H10: =SUMIFS(Calendar!$G$2:$G$176,Calendar!$C$2:$C$176,G10) -> 889741.51 | I10: 0.01 | J10: =H10*I10 -> 8897.4151 | K10: 0.01 | L10: 0 | M10: =J10*(1-K10*L10) -> 8897.4151 | N10: =IF(K10>0,D10+1,"-") -> 11 | O10: normal
A11: SAAS-ANNUAL | B11: Gorgias | C11: other_ap | D11: 5 | E11: 9 | F11: =E11 -> 9 | J11: 9000 | K11: 0 | L11: 0 | M11: =J11*(1-K11*L11) -> 9000 | N11: =IF(K11>0,D11+1,"-") -> - | O11: low
A13: Set column L to 1 and column F to the discount deadline to take an early-pay discount; the Forecast tab updates.

Sheet Check
A1: Workbook vs Python engine (world/engine.py), same inputs
A2: Column C is pasted from a Python run; column B is this workbook's formula result.
A4: Week starting | B4: Workbook closing cash | C4: Python closing cash | D4: Difference | E4: Difference %
A5: =Forecast!N5 -> 46321 | B5: =Forecast!N37 -> 428959.74 | C5: 428959.74 | D5: =B5-C5 -> -0.0013463073 | E5: =IF(C5=0,0,D5/C5) -> -3.1385401e-09
A6: =Forecast!O5 -> 46328 | B6: =Forecast!O37 -> 567282.13 | C6: 567282.13 | D6: =B6-C6 -> -0.00093989877 | E6: =IF(C6=0,0,D6/C6) -> -1.6568454e-09
A7: =Forecast!P5 -> 46335 | B7: =Forecast!P37 -> 803901.62 | C7: 803901.62 | D7: =B7-C7 -> 0.00404084 | E7: =IF(C7=0,0,D7/C7) -> 5.0265354e-09
A8: =Forecast!Q5 -> 46342 | B8: =Forecast!Q37 -> 194498.07 | C8: 194498.07 | D8: =B8-C8 -> -0.0048827989 | E8: =IF(C8=0,0,D8/C8) -> -2.5104614e-08
A9: =Forecast!R5 -> 46349 | B9: =Forecast!R37 -> 595308.01 | C9: 595308.01 | D9: =B9-C9 -> -0.0046445895 | E9: =IF(C9=0,0,D9/C9) -> -7.801994e-09
A10: =Forecast!S5 -> 46356 | B10: =Forecast!S37 -> 807895.22 | C10: 807895.22 | D10: =B10-C10 -> -0.00075701333 | E10: =IF(C10=0,0,D10/C10) -> -9.370192e-10
A11: =Forecast!T5 -> 46363 | B11: =Forecast!T37 -> 992298.88 | C11: 992298.88 | D11: =B11-C11 -> -0.00076523924 | E11: =IF(C11=0,0,D11/C11) -> -7.7117817e-10
A12: =Forecast!U5 -> 46370 | B12: =Forecast!U37 -> 1104975 | C12: 1104975 | D12: =B12-C12 -> -0.00061653159 | E12: =IF(C12=0,0,D12/C12) -> -5.5795977e-10
A13: =Forecast!V5 -> 46377 | B13: =Forecast!V37 -> 1084791.3 | C13: 1084791.3 | D13: =B13-C13 -> -0.00034054415 | E13: =IF(C13=0,0,D13/C13) -> -3.1392596e-10
A14: =Forecast!W5 -> 46384 | B14: =Forecast!W37 -> 1163983.6 | C14: 1163983.6 | D14: =B14-C14 -> -0.0030990622 | E14: =IF(C14=0,0,D14/C14) -> -2.6624622e-09
A15: =Forecast!X5 -> 46391 | B15: =Forecast!X37 -> 968080.37 | C15: 968080.37 | D15: =B15-C15 -> 0.0021081807 | E15: =IF(C15=0,0,D15/C15) -> 2.1776918e-09
A16: =Forecast!Y5 -> 46398 | B16: =Forecast!Y37 -> 1015386.7 | C16: 1015386.7 | D16: =B16-C16 -> -0.0034183044 | E16: =IF(C16=0,0,D16/C16) -> -3.366505e-09
A17: =Forecast!Z5 -> 46405 | B17: =Forecast!Z37 -> 889387.84 | C17: 889387.84 | D17: =B17-C17 -> -0.0015167712 | E17: =IF(C17=0,0,D17/C17) -> -1.7054103e-09
A19: Largest difference % | B19: =MAX(MAX(E5:E17),-MIN(E5:E17)) -> 2.5104614e-08
A20: Python low point | B20: 194498.07
A21: Workbook low point | B21: =Forecast!B44 -> 194498.07
